Workbook

Sheet Summary
A1: SBERT Paper Replication — Summary of Results
A2: Sentence-BERT (Reimers & Gurevych, EMNLP 2019). Replicated = base-model runs from your notebooks. All values ×100 (WikiSec accuracy shown as %).
A4: Table / model | B4: Metric | C4: Paper | D4: Replicated | E4: Difference
A5: Table 1 — SBERT-NLI-base | B5: Avg Spearman (7 STS) | C5: =Table1_STS_Unsupervised!B12 -> 74.89 | D5: =Table1_STS_Unsupervised!C12 -> 73.882322 | E5: =D5-C5 -> -1.0076784
A6: Table 1 — SRoBERTa-NLI-base | B6: Avg Spearman (7 STS) | C6: =Table1_STS_Unsupervised!E12 -> 74.212857 | D6: =Table1_STS_Unsupervised!F12 -> 75.061649 | E6: =D6-C6 -> 0.84879171
A7: Table 2 — SBERT-STSb-base | B7: STSb Spearman (10-seed mean) | C7: =Table2_STSb_Supervised!C5 -> 84.67 | D7: =Table2_STSb_Supervised!E5 -> 84.071606 | E7: =D7-C7 -> -0.5983936
A8: Table 2 — SRoBERTa-STSb-base | B8: STSb Spearman (10-seed mean) | C8: =Table2_STSb_Supervised!C6 -> 84.92 | D8: =Table2_STSb_Supervised!E6 -> 85.142153 | E8: =D8-C8 -> 0.2221533
A9: Table 2 — SBERT-NLI-STSb-base | B9: STSb Spearman (10-seed mean) | C9: =Table2_STSb_Supervised!C7 -> 85.35 | D9: =Table2_STSb_Supervised!E7 -> 84.509603 | E9: =D9-C9 -> -0.8403969
A10: Table 2 — SRoBERTa-NLI-STSb-base | B10: STSb Spearman (10-seed mean) | C10: =Table2_STSb_Supervised!C8 -> 84.79 | D10: =Table2_STSb_Supervised!E8 -> 85.142153 | E10: =D10-C10 -> 0.3521533
A11: Table 3 — AFS 10-fold CV | B11: Pearson r | C11: =Table3_AFS!B5 -> 76.57 | D11: =Table3_AFS!C5 -> 75.871366 | E11: =D11-C11 -> -0.69863432
A12: Table 3 — AFS cross-topic | B12: Pearson r | C12: =Table3_AFS!B6 -> 52.34 | D12: =Table3_AFS!C6 -> 51.212242 | E12: =D12-C12 -> -1.1277581
A13: Table 4 — SBERT-WikiSec-base | B13: Accuracy (%) | C13: =Table4_WikiSec!B5*100 -> 80.42 | D13: =Table4_WikiSec!B6*100 -> 79.000884 | E13: =D13-C13 -> -1.4191164
A14: Table 5 — SBERT-NLI-base | B14: Avg accuracy (7 tasks) | C14: =Table5_SentEval!I5 -> 87.411429 | D14: =Table5_SentEval!I6 -> 86.65 | E14: =D14-C14 -> -0.76142857

Sheet Table1_STS_Unsupervised
A1: Table 1 — Unsupervised STS (Spearman × 100): Paper vs Replicated
A2: Paper: Reimers & Gurevych (2019), Table 1. Replicated: 02_SBERT_STS_Evaluation_table1.ipynb (SBERT-NLI-base) and 03_SRoBERTa_NLI_Training_and_STS_Eval_Table1.ipynb (SRoBERTa-NLI-base).
A4: Dataset | B4: SBERT-NLI-base Paper | C4: SBERT-NLI-base Replicated | D4: SBERT-NLI-base Difference | E4: SRoBERTa-NLI-base Paper | F4: SRoBERTa-NLI-base Replicated | G4: SRoBERTa-NLI-base Difference
A5: STS12 | B5: 70.97 | C5: 70.664484 | D5: =C5-B5 -> -0.305516 | E5: 71.54 | F5: 72.614462 | G5: =F5-E5 -> 1.074462
A6: STS13 | B6: 76.53 | C6: 72.778056 | D6: =C6-B6 -> -3.751944 | E6: 72.49 | F6: 73.975465 | G6: =F6-E6 -> 1.485465
A7: STS14 | B7: 73.19 | C7: 70.662632 | D7: =C7-B7 -> -2.527368 | E7: 70.8 | F7: 71.350673 | G7: =F7-E7 -> 0.550673
A8: STS15 | B8: 79.09 | C8: 78.869953 | D8: =C8-B8 -> -0.220047 | E8: 78.74 | F8: 79.862134 | G8: =F8-E8 -> 1.122134
A9: STS16 | B9: 74.3 | C9: 74.05885 | D9: =C9-B9 -> -0.24115 | E9: 73.69 | F9: 76.457147 | G9: =F9-E9 -> 2.767147
A10: STSb | B10: 77.03 | C10: 76.77926 | D10: =C10-B10 -> -0.25074 | E10: 77.77 | F10: 77.776534 | G10: =F10-E10 -> 0.006534
A11: SICK-R | B11: 72.91 | C11: 73.363016 | D11: =C11-B11 -> 0.453016 | E11: 74.46 | F11: 73.395127 | G11: =F11-E11 -> -1.064873
A12: Average | B12: 74.89 | C12: =AVERAGE(C5:C11) -> 73.882322 | D12: =C12-B12 -> -1.0076784 | E12: =AVERAGE(E5:E11) -> 74.212857 | F12: =AVERAGE(F5:F11) -> 75.061649 | G12: =F12-E12 -> 0.84879171
A14: Note: averages are computed from the seven dataset rows; the paper prints 74.89 / 74.21 (rounding).

Sheet Table2_STSb_Supervised
A1: Table 2 — STS Benchmark Test Set (Spearman × 100): Paper vs Replicated
A2: Paper: Reimers & Gurevych (2019), Table 2. Replicated: 10-seed runs (seeds 42–51), 4 epochs; per-seed detail in Table2_Seeds.
A4: Model | B4: Training setup | C4: Paper mean | D4: Paper std | E4: Replicated mean (10 seeds) | F4: Replicated std | G4: Difference (mean)
A5: SBERT-STSb-base | B5: STSb only | C5: 84.67 | D5: 0.19 | E5: =AVERAGE(Table2_Seeds!D6:D15) -> 84.071606 | F5: =STDEV(Table2_Seeds!D6:D15) -> 0.48931067 | G5: =E5-C5 -> -0.5983936
A6: SRoBERTa-STSb-base | B6: STSb only | C6: 84.92 | D6: 0.34 | E6: =AVERAGE(Table2_Seeds!D23:D32) -> 85.142153 | F6: =STDEV(Table2_Seeds!D23:D32) -> 0.19444198 | G6: =E6-C6 -> 0.2221533
A7: SBERT-NLI-STSb-base | B7: NLI + STSb | C7: 85.35 | D7: 0.17 | E7: =AVERAGE(Table2_Seeds!D40:D49) -> 84.509603 | F7: =STDEV(Table2_Seeds!D40:D49) -> 0.23693229 | G7: =E7-C7 -> -0.8403969
A8: SRoBERTa-NLI-STSb-base | B8: NLI + STSb | C8: 84.79 | D8: 0.38 | E8: =AVERAGE(Table2_Seeds!D57:D66) -> 85.142153 | F8: =STDEV(Table2_Seeds!D57:D66) -> 0.19444198 | G8: =E8-C8 -> 0.3521533

Sheet Table2_Seeds
A1: Table 2 — 10-seed replication detail
A2: Each block = one paper row. Checkpoints: own locally trained models. Sample std (n−1).
A4: SBERT-STSb-base
A5: Seed | B5: Best epoch | C5: Best dev Spearman | D5: Test Spearman | E5: Runtime (min)
A6: 42 | B6: 3 | C6: 87.533064 | D6: 84.30618 | E6: 7.541019
A7: 43 | B7: 3 | C7: 87.365492 | D7: 83.684361 | E7: 7.515456
A8: 44 | B8: 4 | C8: 87.333445 | D8: 84.437164 | E8: 7.503073
A9: 45 | B9: 3 | C9: 86.998394 | D9: 83.834628 | E9: 7.513634
A10: 46 | B10: 4 | C10: 87.364162 | D10: 83.751215 | E10: 7.545202
A11: 47 | B11: 1 | C11: 87.33786 | D11: 83.016717 | E11: 7.487074
A12: 48 | B12: 4 | C12: 87.497312 | D12: 84.599774 | E12: 7.537637
A13: 49 | B13: 4 | C13: 87.44419 | D13: 84.336687 | E13: 7.497972
A14: 50 | B14: 3 | C14: 87.234323 | D14: 84.298234 | E14: 7.492855
A15: 51 | B15: 4 | C15: 87.691471 | D15: 84.451104 | E15: 7.506622
A16: Mean | C16: =AVERAGE(C6:C15) -> 87.379971 | D16: =AVERAGE(D6:D15) -> 84.071606 | E16: =AVERAGE(E6:E15) -> 7.5140544
A17: Std dev (sample) | C17: =STDEV(C6:C15) -> 0.18546477 | D17: =STDEV(D6:D15) -> 0.48931067
A18: Min | C18: =MIN(C6:C15) -> 86.998394 | D18: =MIN(D6:D15) -> 83.016717
A19: Max | C19: =MAX(C6:C15) -> 87.691471 | D19: =MAX(D6:D15) -> 84.599774
A21: SRoBERTa-STSb-base
A22: Seed | B22: Best epoch | C22: Best dev Spearman | D22: Test Spearman | E22: Runtime (min)
A23: 42 | B23: 2 | C23: 88.113307 | D23: 84.844225 | E23: 8.112883
A24: 43 | B24: 3 | C24: 88.337703 | D24: 85.357565 | E24: 8.065814
A25: 44 | B25: 4 | C25: 88.228111 | D25: 85.015403 | E25: 8.089954
A26: 45 | B26: 4 | C26: 88.192417 | D26: 85.089609 | E26: 8.093529
A27: 46 | B27: 4 | C27: 88.104054 | D27: 85.212165 | E27: 8.14038
A28: 47 | B28: 4 | C28: 88.313715 | D28: 85.382724 | E28: 8.077633
A29: 48 | B29: 3 | C29: 88.107287 | D29: 85.054695 | E29: 8.040074
A30: 49 | B30: 4 | C30: 88.232799 | D30: 85.359354 | E30: 8.047646
A31: 50 | B31: 3 | C31: 88.402252 | D31: 85.215292 | E31: 8.056223
A32: 51 | B32: 2 | C32: 88.02176 | D32: 84.890501 | E32: 8.069903
A33: Mean | C33: =AVERAGE(C23:C32) -> 88.205341 | D33: =AVERAGE(D23:D32) -> 85.142153 | E33: =AVERAGE(E23:E32) -> 8.0794039
A34: Std dev (sample) | C34: =STDEV(C23:C32) -> 0.12088741 | D34: =STDEV(D23:D32) -> 0.19444198
A35: Min | C35: =MIN(C23:C32) -> 88.02176 | D35: =MIN(D23:D32) -> 84.844225
A36: Max | C36: =MAX(C23:C32) -> 88.402252 | D36: =MAX(D23:D32) -> 85.382724
A38: SBERT-NLI-STSb-base
A39: Seed | B39: Best epoch | C39: Best dev Spearman | D39: Test Spearman | E39: Runtime (min)
A40: 42 | B40: 4 | C40: 86.604225 | D40: 84.471953 | E40: 9.187636
A41: 43 | B41: 4 | C41: 86.444431 | D41: 84.323734 | E41: 9.037125
A42: 44 | B42: 4 | C42: 86.415619 | D42: 84.778752 | E42: 8.929841
A43: 45 | B43: 3 | C43: 86.809433 | D43: 84.267421 | E43: 9.813706
...

Sheet Table3_AFS
A1: Table 3 — Argument Facet Similarity (AFS), SBERT-AFS-base: Paper vs Replicated
A2: Paper: Reimers & Gurevych (2019), Table 3. Replicated: 06_SBERT_AFS.ipynb (bert-base-uncased, regression objective, 4 epochs). Fold and topic detail below.
A4: Evaluation | B4: Paper Pearson (r) | C4: Replicated Pearson (r) | D4: Difference (r) | E4: Paper Spearman (ρ) | F4: Replicated Spearman (ρ) | G4: Difference (ρ)
A5: 10-fold cross-validation | B5: 76.57 | C5: =B21 -> 75.871366 | D5: =C5-B5 -> -0.69863432 | E5: 74.13 | F5: =C21 -> 73.205895 | G5: =F5-E5 -> -0.92410533
A6: Cross-topic | B6: 52.34 | C6: =B29 -> 51.212242 | D6: =C6-B6 -> -1.1277581 | E6: 50.65 | F6: =C29 -> 49.202554 | G6: =F6-E6 -> -1.4474459
A9: Detail — 10-fold CV per fold (replicated)
A10: Fold | B10: Pearson | C10: Spearman
A11: 1 | B11: 75.764964 | C11: 73.902103
A12: 2 | B12: 77.309159 | C12: 74.557891
A13: 3 | B13: 76.064529 | C13: 72.612828
A14: 4 | B14: 77.456202 | C14: 74.415604
A15: 5 | B15: 78.751784 | C15: 75.791955
A16: 6 | B16: 72.867518 | C16: 70.729107
A17: 7 | B17: 77.438501 | C17: 76.221085
A18: 8 | B18: 74.05753 | C18: 71.63134
A19: 9 | B19: 75.674677 | C19: 72.339987
A20: 10 | B20: 73.328793 | C20: 69.857045
A21: Mean | B21: =AVERAGE(B11:B20) -> 75.871366 | C21: =AVERAGE(C11:C20) -> 73.205895
A22: Std dev (sample) | B22: =STDEV(B11:B20) -> 1.9492668 | C22: =STDEV(C11:C20) -> 2.12093
A24: Detail — cross-topic per held-out topic (replicated)
A25: Held-out topic | B25: Pearson | C25: Spearman
A26: death_penalty | B26: 51.5595 | C26: 50.83446
A27: gay_marriage | B27: 36.275879 | C27: 32.6152
A28: gun_control | B28: 65.801347 | C28: 64.158003
A29: Mean | B29: =AVERAGE(B26:B28) -> 51.212242 | C29: =AVERAGE(C26:C28) -> 49.202554

Sheet Table4_WikiSec
A1: Table 4 — Wikipedia Section Triplets (Accuracy), SBERT-WikiSec-base: Paper vs Replicated
A2: Paper: Reimers & Gurevych (2019), Table 4. Replicated: 07_SBERT_WikiSec_Base_Table4.ipynb (triplet loss, 1 epoch, 222,957 test triplets).
A4: SBERT-WikiSec-base | B4: Accuracy
A5: Paper | B5: 0.8042
A6: Replicated | B6: 0.79000884
A7: Difference (Replicated − Paper) | B7: =B6-B5 -> -0.014191164
A9: Extra: replicated dev accuracy after epoch 1 | B9: 0.7898

Sheet Table5_SentEval
A1: Table 5 — SentEval Transfer Accuracy, SBERT-NLI-base: Paper vs Replicated
A2: Paper: Reimers & Gurevych (2019), Table 5. Replicated: 05_SBERT_SentEval.ipynb (SentEval logistic regression; notebook task name SST2 = paper's SST).
A4: SBERT-NLI-base | B4: MR | C4: CR | D4: SUBJ | E4: MPQA | F4: SST | G4: TREC | H4: MRPC | I4: Average
A5: Paper | B5: 83.64 | C5: 89.43 | D5: 94.39 | E5: 89.86 | F5: 88.96 | G5: 89.6 | H5: 76 | I5: =AVERAGE(B5:H5) -> 87.411429
A6: Replicated | B6: 82.14 | C6: 88.77 | D6: 93.09 | E6: 89.91 | F6: 88.41 | G6: 88 | H6: 76.23 | I6: =AVERAGE(B6:H6) -> 86.65
A7: Difference (Replicated − Paper) | B7: =B6-B5 -> -1.5 | C7: =C6-C5 -> -0.66 | D7: =D6-D5 -> -1.3 | E7: =E6-E5 -> 0.05 | F7: =F6-F5 -> -0.55 | G7: =G6-G5 -> -1.6 | H7: =H6-H5 -> 0.23 | I7: =I6-I5 -> -0.76142857
